Loaded module: python3/3.6.2
Loaded dependency [numpy/1.13.1-python-3.6.2-openblas-0.2.20]: openblas/0.2.20
Loaded module: numpy/1.13.1-python-3.6.2-openblas-0.2.20

Loading numpy/1.13.1-python-3.6.2-openblas-0.2.20
  Loading requirement: openblas/0.2.20
Loaded module: scipy/0.19.1-python-3.6.2
Loaded module: matplotlib/2.0.2-python-3.6.2
Loaded module: cuda/11.6
/zhome/8d/a/147395/miniconda3/envs/multimodel2/lib/python3.10/site-packages/huggingface_hub/file_download.py:1132: FutureWarning: `resume_download` is deprecated and will be removed in version 1.0.0. Downloads always resume when possible. If you want to force a new download, use `force_download=True`.
  warnings.warn(
Traceback (most recent call last):
  File "/zhome/8d/a/147395/miniconda3/envs/multimodel2/lib/python3.10/site-packages/huggingface_hub/utils/_errors.py", line 304, in hf_raise_for_status
    response.raise_for_status()
  File "/zhome/8d/a/147395/miniconda3/envs/multimodel2/lib/python3.10/site-packages/requests/models.py", line 1021, in raise_for_status
    raise HTTPError(http_error_msg, response=self)
requests.exceptions.HTTPError: 401 Client Error: Unauthorized for url: https://huggingface.co/mymodel/resolve/main/tokenizer_config.json

The above exception was the direct cause of the following exception:

Traceback (most recent call last):
  File "/zhome/8d/a/147395/miniconda3/envs/multimodel2/lib/python3.10/site-packages/transformers/utils/hub.py", line 398, in cached_file
    resolved_file = hf_hub_download(
  File "/zhome/8d/a/147395/miniconda3/envs/multimodel2/lib/python3.10/site-packages/huggingface_hub/utils/_validators.py", line 114, in _inner_fn
    return fn(*args, **kwargs)
  File "/zhome/8d/a/147395/miniconda3/envs/multimodel2/lib/python3.10/site-packages/huggingface_hub/file_download.py", line 1221, in hf_hub_download
    return _hf_hub_download_to_cache_dir(
  File "/zhome/8d/a/147395/miniconda3/envs/multimodel2/lib/python3.10/site-packages/huggingface_hub/file_download.py", line 1325, in _hf_hub_download_to_cache_dir
    _raise_on_head_call_error(head_call_error, force_download, local_files_only)
  File "/zhome/8d/a/147395/miniconda3/envs/multimodel2/lib/python3.10/site-packages/huggingface_hub/file_download.py", line 1823, in _raise_on_head_call_error
    raise head_call_error
  File "/zhome/8d/a/147395/miniconda3/envs/multimodel2/lib/python3.10/site-packages/huggingface_hub/file_download.py", line 1722, in _get_metadata_or_catch_error
    metadata = get_hf_file_metadata(url=url, proxies=proxies, timeout=etag_timeout, headers=headers)
  File "/zhome/8d/a/147395/miniconda3/envs/multimodel2/lib/python3.10/site-packages/huggingface_hub/utils/_validators.py", line 114, in _inner_fn
    return fn(*args, **kwargs)
  File "/zhome/8d/a/147395/miniconda3/envs/multimodel2/lib/python3.10/site-packages/huggingface_hub/file_download.py", line 1645, in get_hf_file_metadata
    r = _request_wrapper(
  File "/zhome/8d/a/147395/miniconda3/envs/multimodel2/lib/python3.10/site-packages/huggingface_hub/file_download.py", line 372, in _request_wrapper
    response = _request_wrapper(
  File "/zhome/8d/a/147395/miniconda3/envs/multimodel2/lib/python3.10/site-packages/huggingface_hub/file_download.py", line 396, in _request_wrapper
    hf_raise_for_status(response)
  File "/zhome/8d/a/147395/miniconda3/envs/multimodel2/lib/python3.10/site-packages/huggingface_hub/utils/_errors.py", line 352, in hf_raise_for_status
    raise RepositoryNotFoundError(message, response) from e
huggingface_hub.utils._errors.RepositoryNotFoundError: 401 Client Error. (Request ID: Root=1-666a9ea0-61bdf45a0282a6cc04613e57;593d3c6b-16e5-48c9-a04b-c98b16771f57)

Repository Not Found for url: https://huggingface.co/mymodel/resolve/main/tokenizer_config.json.
Please make sure you specified the correct `repo_id` and `repo_type`.
If you are trying to access a private or gated repo, make sure you are authenticated.
Invalid username or password.

The above exception was the direct cause of the following exception:

Traceback (most recent call last):
  File "/zhome/8d/a/147395/masterproject/masterproject/src/multimodal/multimodalattention/multimodel.py", line 195, in <module>
    tokenizer = AutoTokenizer.from_pretrained(
  File "/zhome/8d/a/147395/miniconda3/envs/multimodel2/lib/python3.10/site-packages/transformers/models/auto/tokenization_auto.py", line 804, in from_pretrained
    tokenizer_config = get_tokenizer_config(pretrained_model_name_or_path, **kwargs)
  File "/zhome/8d/a/147395/miniconda3/envs/multimodel2/lib/python3.10/site-packages/transformers/models/auto/tokenization_auto.py", line 637, in get_tokenizer_config
    resolved_config_file = cached_file(
  File "/zhome/8d/a/147395/miniconda3/envs/multimodel2/lib/python3.10/site-packages/transformers/utils/hub.py", line 421, in cached_file
    raise EnvironmentError(
OSError: mymodel is not a local folder and is not a valid model identifier listed on 'https://huggingface.co/models'
If this is a private repository, make sure to pass a token having permission to this repo either by logging in with `huggingface-cli login` or by passing `token=<your_token>`
